<?xml version="1.0" encoding="UTF-8"?>
<testng-results ignored="0" total="10" passed="5" failed="5" skipped="0">
  <reporter-output>
  </reporter-output>
  <suite started-at="2022-06-27T17:33:50 IST" name="Default suite" finished-at="2022-06-27T17:40:25 IST" duration-ms="395207">
    <groups>
    </groups>
    <test started-at="2022-06-27T17:33:50 IST" name="Default test" finished-at="2022-06-27T17:40:25 IST" duration-ms="395207">
      <class name="Loginautomation">
        <test-method signature="Test1()[pri:0, instance:Loginautomation@6d4e5011]" started-at="2022-06-27T17:33:50 IST" name="Test1" finished-at="2022-06-27T17:34:01 IST" duration-ms="11115" status="FAIL">
          <exception class="java.lang.AssertionError">
            <message>
              <![CDATA[Not Validinput did not expect [https://testing-assessment-foh15kew9-edvora.vercel.app/r] but found [https://testing-assessment-foh15kew9-edvora.vercel.app/r]]]>
            </message>
            <full-stacktrace>
              <![CDATA[java.lang.AssertionError: Not Validinput did not expect [https://testing-assessment-foh15kew9-edvora.vercel.app/r] but found [https://testing-assessment-foh15kew9-edvora.vercel.app/r]
at org.testng.Assert.fail(Assert.java:99)
at org.testng.Assert.failEquals(Assert.java:1041)
at org.testng.Assert.assertNotEqualsImpl(Assert.java:147)
at org.testng.Assert.assertNotEquals(Assert.java:1531)
at Loginautomation.reginput(Loginautomation.java:251)
at Loginautomation.Test1(Loginautomation.java:84)
at java.base/jdk.internal.reflect.DirectMethodHandleAccessor.invoke(DirectMethodHandleAccessor.java:104)
at java.base/java.lang.reflect.Method.invoke(Method.java:577)
at org.testng.internal.MethodInvocationHelper.invokeMethod(MethodInvocationHelper.java:133)
at org.testng.internal.TestInvoker.invokeMethod(TestInvoker.java:598)
at org.testng.internal.TestInvoker.invokeTestMethod(TestInvoker.java:173)
at org.testng.internal.MethodRunner.runInSequence(MethodRunner.java:46)
at org.testng.internal.TestInvoker$MethodInvocationAgent.invoke(TestInvoker.java:824)
at org.testng.internal.TestInvoker.invokeTestMethods(TestInvoker.java:146)
at org.testng.internal.TestMethodWorker.invokeTestMethods(TestMethodWorker.java:146)
at org.testng.internal.TestMethodWorker.run(TestMethodWorker.java:128)
at java.base/java.util.ArrayList.forEach(ArrayList.java:1511)
at org.testng.TestRunner.privateRun(TestRunner.java:794)
at org.testng.TestRunner.run(TestRunner.java:596)
at org.testng.SuiteRunner.runTest(SuiteRunner.java:377)
at org.testng.SuiteRunner.runSequentially(SuiteRunner.java:371)
at org.testng.SuiteRunner.privateRun(SuiteRunner.java:332)
at org.testng.SuiteRunner.run(SuiteRunner.java:276)
at org.testng.SuiteRunnerWorker.runSuite(SuiteRunnerWorker.java:53)
at org.testng.SuiteRunnerWorker.run(SuiteRunnerWorker.java:96)
at org.testng.TestNG.runSuitesSequentially(TestNG.java:1212)
at org.testng.TestNG.runSuitesLocally(TestNG.java:1134)
at org.testng.TestNG.runSuites(TestNG.java:1063)
at org.testng.TestNG.run(TestNG.java:1031)
at org.testng.remote.AbstractRemoteTestNG.run(AbstractRemoteTestNG.java:115)
at org.testng.remote.RemoteTestNG.initAndRun(RemoteTestNG.java:251)
at org.testng.remote.RemoteTestNG.main(RemoteTestNG.java:77)
]]>
            </full-stacktrace>
          </exception> <!-- java.lang.AssertionError -->
          <reporter-output>
          </reporter-output>
        </test-method> <!-- Test1 -->
        <test-method signature="Test10()[pri:0, instance:Loginautomation@6d4e5011]" started-at="2022-06-27T17:34:01 IST" name="Test10" finished-at="2022-06-27T17:34:38 IST" duration-ms="37014" status="PASS">
          <reporter-output>
          </reporter-output>
        </test-method> <!-- Test10 -->
        <test-method signature="Test2()[pri:0, instance:Loginautomation@6d4e5011]" started-at="2022-06-27T17:34:38 IST" name="Test2" finished-at="2022-06-27T17:35:07 IST" duration-ms="28915" status="FAIL">
          <exception class="java.lang.AssertionError">
            <message>
              <![CDATA[Valid input expected [https://testing-assessment-foh15kew9-edvora.vercel.app/s] but found [https://testing-assessment-foh15kew9-edvora.vercel.app/]]]>
            </message>
            <full-stacktrace>
              <![CDATA[java.lang.AssertionError: Valid input expected [https://testing-assessment-foh15kew9-edvora.vercel.app/s] but found [https://testing-assessment-foh15kew9-edvora.vercel.app/]
at org.testng.Assert.fail(Assert.java:99)
at org.testng.Assert.failNotEquals(Assert.java:1037)
at org.testng.Assert.assertEqualsImpl(Assert.java:140)
at org.testng.Assert.assertEquals(Assert.java:122)
at org.testng.Assert.assertEquals(Assert.java:629)
at Loginautomation.logininput(Loginautomation.java:203)
at Loginautomation.Test2(Loginautomation.java:94)
at java.base/jdk.internal.reflect.DirectMethodHandleAccessor.invoke(DirectMethodHandleAccessor.java:104)
at java.base/java.lang.reflect.Method.invoke(Method.java:577)
at org.testng.internal.MethodInvocationHelper.invokeMethod(MethodInvocationHelper.java:133)
at org.testng.internal.TestInvoker.invokeMethod(TestInvoker.java:598)
at org.testng.internal.TestInvoker.invokeTestMethod(TestInvoker.java:173)
at org.testng.internal.MethodRunner.runInSequence(MethodRunner.java:46)
at org.testng.internal.TestInvoker$MethodInvocationAgent.invoke(TestInvoker.java:824)
at org.testng.internal.TestInvoker.invokeTestMethods(TestInvoker.java:146)
at org.testng.internal.TestMethodWorker.invokeTestMethods(TestMethodWorker.java:146)
at org.testng.internal.TestMethodWorker.run(TestMethodWorker.java:128)
at java.base/java.util.ArrayList.forEach(ArrayList.java:1511)
at org.testng.TestRunner.privateRun(TestRunner.java:794)
at org.testng.TestRunner.run(TestRunner.java:596)
at org.testng.SuiteRunner.runTest(SuiteRunner.java:377)
at org.testng.SuiteRunner.runSequentially(SuiteRunner.java:371)
at org.testng.SuiteRunner.privateRun(SuiteRunner.java:332)
at org.testng.SuiteRunner.run(SuiteRunner.java:276)
at org.testng.SuiteRunnerWorker.runSuite(SuiteRunnerWorker.java:53)
at org.testng.SuiteRunnerWorker.run(SuiteRunnerWorker.java:96)
at org.testng.TestNG.runSuitesSequentially(TestNG.java:1212)
at org.testng.TestNG.runSuitesLocally(TestNG.java:1134)
at org.testng.TestNG.runSuites(TestNG.java:1063)
at org.testng.TestNG.run(TestNG.java:1031)
at org.testng.remote.AbstractRemoteTestNG.run(AbstractRemoteTestNG.java:115)
at org.testng.remote.RemoteTestNG.initAndRun(RemoteTestNG.java:251)
at org.testng.remote.RemoteTestNG.main(RemoteTestNG.java:77)
]]>
            </full-stacktrace>
          </exception> <!-- java.lang.AssertionError -->
          <reporter-output>
          </reporter-output>
        </test-method> <!-- Test2 -->
        <test-method signature="Test3()[pri:0, instance:Loginautomation@6d4e5011]" started-at="2022-06-27T17:35:07 IST" name="Test3" finished-at="2022-06-27T17:35:43 IST" duration-ms="35358" status="FAIL">
          <exception class="java.lang.AssertionError">
            <message>
              <![CDATA[Not Validinput did not expect [https://testing-assessment-foh15kew9-edvora.vercel.app/s] but found [https://testing-assessment-foh15kew9-edvora.vercel.app/s]]]>
            </message>
            <full-stacktrace>
              <![CDATA[java.lang.AssertionError: Not Validinput did not expect [https://testing-assessment-foh15kew9-edvora.vercel.app/s] but found [https://testing-assessment-foh15kew9-edvora.vercel.app/s]
at org.testng.Assert.fail(Assert.java:99)
at org.testng.Assert.failEquals(Assert.java:1041)
at org.testng.Assert.assertNotEqualsImpl(Assert.java:147)
at org.testng.Assert.assertNotEquals(Assert.java:1531)
at Loginautomation.logininput(Loginautomation.java:204)
at Loginautomation.Test3(Loginautomation.java:105)
at java.base/jdk.internal.reflect.DirectMethodHandleAccessor.invoke(DirectMethodHandleAccessor.java:104)
at java.base/java.lang.reflect.Method.invoke(Method.java:577)
at org.testng.internal.MethodInvocationHelper.invokeMethod(MethodInvocationHelper.java:133)
at org.testng.internal.TestInvoker.invokeMethod(TestInvoker.java:598)
at org.testng.internal.TestInvoker.invokeTestMethod(TestInvoker.java:173)
at org.testng.internal.MethodRunner.runInSequence(MethodRunner.java:46)
at org.testng.internal.TestInvoker$MethodInvocationAgent.invoke(TestInvoker.java:824)
at org.testng.internal.TestInvoker.invokeTestMethods(TestInvoker.java:146)
at org.testng.internal.TestMethodWorker.invokeTestMethods(TestMethodWorker.java:146)
at org.testng.internal.TestMethodWorker.run(TestMethodWorker.java:128)
at java.base/java.util.ArrayList.forEach(ArrayList.java:1511)
at org.testng.TestRunner.privateRun(TestRunner.java:794)
at org.testng.TestRunner.run(TestRunner.java:596)
at org.testng.SuiteRunner.runTest(SuiteRunner.java:377)
at org.testng.SuiteRunner.runSequentially(SuiteRunner.java:371)
at org.testng.SuiteRunner.privateRun(SuiteRunner.java:332)
at org.testng.SuiteRunner.run(SuiteRunner.java:276)
at org.testng.SuiteRunnerWorker.runSuite(SuiteRunnerWorker.java:53)
at org.testng.SuiteRunnerWorker.run(SuiteRunnerWorker.java:96)
at org.testng.TestNG.runSuitesSequentially(TestNG.java:1212)
at org.testng.TestNG.runSuitesLocally(TestNG.java:1134)
at org.testng.TestNG.runSuites(TestNG.java:1063)
at org.testng.TestNG.run(TestNG.java:1031)
at org.testng.remote.AbstractRemoteTestNG.run(AbstractRemoteTestNG.java:115)
at org.testng.remote.RemoteTestNG.initAndRun(RemoteTestNG.java:251)
at org.testng.remote.RemoteTestNG.main(RemoteTestNG.java:77)
]]>
            </full-stacktrace>
          </exception> <!-- java.lang.AssertionError -->
          <reporter-output>
          </reporter-output>
        </test-method> <!-- Test3 -->
        <test-method signature="Test4()[pri:0, instance:Loginautomation@6d4e5011]" started-at="2022-06-27T17:35:43 IST" name="Test4" finished-at="2022-06-27T17:36:04 IST" duration-ms="21050" status="FAIL">
          <exception class="java.lang.AssertionError">
            <message>
              <![CDATA[Valid input expected [https://testing-assessment-foh15kew9-edvora.vercel.app/s] but found [https://testing-assessment-foh15kew9-edvora.vercel.app/]]]>
            </message>
            <full-stacktrace>
              <![CDATA[java.lang.AssertionError: Valid input expected [https://testing-assessment-foh15kew9-edvora.vercel.app/s] but found [https://testing-assessment-foh15kew9-edvora.vercel.app/]
at org.testng.Assert.fail(Assert.java:99)
at org.testng.Assert.failNotEquals(Assert.java:1037)
at org.testng.Assert.assertEqualsImpl(Assert.java:140)
at org.testng.Assert.assertEquals(Assert.java:122)
at org.testng.Assert.assertEquals(Assert.java:629)
at Loginautomation.logininput(Loginautomation.java:203)
at Loginautomation.Test4(Loginautomation.java:115)
at java.base/jdk.internal.reflect.DirectMethodHandleAccessor.invoke(DirectMethodHandleAccessor.java:104)
at java.base/java.lang.reflect.Method.invoke(Method.java:577)
at org.testng.internal.MethodInvocationHelper.invokeMethod(MethodInvocationHelper.java:133)
at org.testng.internal.TestInvoker.invokeMethod(TestInvoker.java:598)
at org.testng.internal.TestInvoker.invokeTestMethod(TestInvoker.java:173)
at org.testng.internal.MethodRunner.runInSequence(MethodRunner.java:46)
at org.testng.internal.TestInvoker$MethodInvocationAgent.invoke(TestInvoker.java:824)
at org.testng.internal.TestInvoker.invokeTestMethods(TestInvoker.java:146)
at org.testng.internal.TestMethodWorker.invokeTestMethods(TestMethodWorker.java:146)
at org.testng.internal.TestMethodWorker.run(TestMethodWorker.java:128)
at java.base/java.util.ArrayList.forEach(ArrayList.java:1511)
at org.testng.TestRunner.privateRun(TestRunner.java:794)
at org.testng.TestRunner.run(TestRunner.java:596)
at org.testng.SuiteRunner.runTest(SuiteRunner.java:377)
at org.testng.SuiteRunner.runSequentially(SuiteRunner.java:371)
at org.testng.SuiteRunner.privateRun(SuiteRunner.java:332)
at org.testng.SuiteRunner.run(SuiteRunner.java:276)
at org.testng.SuiteRunnerWorker.runSuite(SuiteRunnerWorker.java:53)
at org.testng.SuiteRunnerWorker.run(SuiteRunnerWorker.java:96)
at org.testng.TestNG.runSuitesSequentially(TestNG.java:1212)
at org.testng.TestNG.runSuitesLocally(TestNG.java:1134)
at org.testng.TestNG.runSuites(TestNG.java:1063)
at org.testng.TestNG.run(TestNG.java:1031)
at org.testng.remote.AbstractRemoteTestNG.run(AbstractRemoteTestNG.java:115)
at org.testng.remote.RemoteTestNG.initAndRun(RemoteTestNG.java:251)
at org.testng.remote.RemoteTestNG.main(RemoteTestNG.java:77)
]]>
            </full-stacktrace>
          </exception> <!-- java.lang.AssertionError -->
          <reporter-output>
          </reporter-output>
        </test-method> <!-- Test4 -->
        <test-method signature="Test5()[pri:0, instance:Loginautomation@6d4e5011]" started-at="2022-06-27T17:36:04 IST" name="Test5" finished-at="2022-06-27T17:36:20 IST" duration-ms="15999" status="FAIL">
          <exception class="java.lang.AssertionError">
            <message>
              <![CDATA[Not Validinput did not expect [https://testing-assessment-foh15kew9-edvora.vercel.app/r] but found [https://testing-assessment-foh15kew9-edvora.vercel.app/r]]]>
            </message>
            <full-stacktrace>
              <![CDATA[java.lang.AssertionError: Not Validinput did not expect [https://testing-assessment-foh15kew9-edvora.vercel.app/r] but found [https://testing-assessment-foh15kew9-edvora.vercel.app/r]
at org.testng.Assert.fail(Assert.java:99)
at org.testng.Assert.failEquals(Assert.java:1041)
at org.testng.Assert.assertNotEqualsImpl(Assert.java:147)
at org.testng.Assert.assertNotEquals(Assert.java:1531)
at Loginautomation.reginput(Loginautomation.java:251)
at Loginautomation.Test5(Loginautomation.java:125)
at java.base/jdk.internal.reflect.DirectMethodHandleAccessor.invoke(DirectMethodHandleAccessor.java:104)
at java.base/java.lang.reflect.Method.invoke(Method.java:577)
at org.testng.internal.MethodInvocationHelper.invokeMethod(MethodInvocationHelper.java:133)
at org.testng.internal.TestInvoker.invokeMethod(TestInvoker.java:598)
at org.testng.internal.TestInvoker.invokeTestMethod(TestInvoker.java:173)
at org.testng.internal.MethodRunner.runInSequence(MethodRunner.java:46)
at org.testng.internal.TestInvoker$MethodInvocationAgent.invoke(TestInvoker.java:824)
at org.testng.internal.TestInvoker.invokeTestMethods(TestInvoker.java:146)
at org.testng.internal.TestMethodWorker.invokeTestMethods(TestMethodWorker.java:146)
at org.testng.internal.TestMethodWorker.run(TestMethodWorker.java:128)
at java.base/java.util.ArrayList.forEach(ArrayList.java:1511)
at org.testng.TestRunner.privateRun(TestRunner.java:794)
at org.testng.TestRunner.run(TestRunner.java:596)
at org.testng.SuiteRunner.runTest(SuiteRunner.java:377)
at org.testng.SuiteRunner.runSequentially(SuiteRunner.java:371)
at org.testng.SuiteRunner.privateRun(SuiteRunner.java:332)
at org.testng.SuiteRunner.run(SuiteRunner.java:276)
at org.testng.SuiteRunnerWorker.runSuite(SuiteRunnerWorker.java:53)
at org.testng.SuiteRunnerWorker.run(SuiteRunnerWorker.java:96)
at org.testng.TestNG.runSuitesSequentially(TestNG.java:1212)
at org.testng.TestNG.runSuitesLocally(TestNG.java:1134)
at org.testng.TestNG.runSuites(TestNG.java:1063)
at org.testng.TestNG.run(TestNG.java:1031)
at org.testng.remote.AbstractRemoteTestNG.run(AbstractRemoteTestNG.java:115)
at org.testng.remote.RemoteTestNG.initAndRun(RemoteTestNG.java:251)
at org.testng.remote.RemoteTestNG.main(RemoteTestNG.java:77)
]]>
            </full-stacktrace>
          </exception> <!-- java.lang.AssertionError -->
          <reporter-output>
          </reporter-output>
        </test-method> <!-- Test5 -->
        <test-method signature="Test6()[pri:0, instance:Loginautomation@6d4e5011]" started-at="2022-06-27T17:36:20 IST" name="Test6" finished-at="2022-06-27T17:37:01 IST" duration-ms="41691" status="PASS">
          <reporter-output>
          </reporter-output>
        </test-method> <!-- Test6 -->
        <test-method signature="Test7()[pri:0, instance:Loginautomation@6d4e5011]" started-at="2022-06-27T17:37:01 IST" name="Test7" finished-at="2022-06-27T17:37:53 IST" duration-ms="51120" status="PASS">
          <reporter-output>
          </reporter-output>
        </test-method> <!-- Test7 -->
        <test-method signature="Test8()[pri:0, instance:Loginautomation@6d4e5011]" started-at="2022-06-27T17:37:53 IST" name="Test8" finished-at="2022-06-27T17:39:41 IST" duration-ms="108443" status="PASS">
          <reporter-output>
          </reporter-output>
        </test-method> <!-- Test8 -->
        <test-method signature="Test9()[pri:0, instance:Loginautomation@6d4e5011]" started-at="2022-06-27T17:39:41 IST" name="Test9" finished-at="2022-06-27T17:40:25 IST" duration-ms="44311" status="PASS">
          <reporter-output>
          </reporter-output>
        </test-method> <!-- Test9 -->
      </class> <!-- Loginautomation -->
    </test> <!-- Default test -->
  </suite> <!-- Default suite -->
</testng-results>
